<?xml version="1.0"?>
<sdf version="1.6">
  <model name="turtlebot3_burger">
    <static>false</static>

    <link name="base_link">
      <!-- Robot Body -->
      <visual name="body_visual">
        <geometry>
          <cylinder>
            <radius>0.1</radius>
            <length>0.1</length>
          </cylinder>
        </geometry>
        <material>
          <ambient>0.2 0.2 0.2 1</ambient>
        </material>
      </visual>

      <!-- Wheels -->
      <joint name="wheel_left_joint" type="continuous">
        <parent>base_link</parent>
        <child>wheel_left</child>
        <axis>
          <xyz>0 1 0</xyz>
          <limit>
            <velocity>10</velocity>
            <effort>10</effort>
          </limit>
        </axis>
      </joint>

      <joint name="wheel_right_joint" type="continuous">
        <parent>base_link</parent>
        <child>wheel_right</child>
        <axis>
          <xyz>0 1 0</xyz>
          <limit>
            <velocity>10</velocity>
            <effort>10</effort>
          </limit>
        </axis>
      </joint>
    </link>

    <!-- Camera Sensor -->
    <link name="camera_link">
      <sensor name="camera" type="camera">
        <always_on>1</always_on>
        <update_rate>30</update_rate>
        <visualize>true</visualize>
        <camera>
          <horizontal_fov>1.3962634</horizontal_fov>
          <image>
            <width>640</width>
            <height>480</height>
            <format>R8G8B8</format>
          </image>
          <clip>
            <near>0.1</near>
            <far>100</far>
          </clip>
        </camera>
        <plugin name="camera_controller" filename="libgazebo_ros_camera.so">
          <ros>
            <namespace>/camera</namespace>
            <remapping>image_raw:=/camera/image_raw</remapping>
          </ros>
        </plugin>
      </sensor>
    </link>

  </model>
</sdf>
